Workbook

Sheet Cover
B2: LEVERAGED BUYOUT MODEL
B3: NovaSaaS Inc. · Radice Capital Partners
B4: Entry EV $485m · 18.5x LTM EBITDA · March 2026
B5: 5-Year Hold · Base Gross IRR 24.0% · MoM 2.9x · Net IRR 20.5%
B6: PRIVATE & CONFIDENTIAL · FICTIONAL CASE STUDY
B9: TABLE OF CONTENTS
B11: 1. Assumptions & Sources / Uses (scenario-driven)
B12: 2. Income Statement
B13: 3. Debt Schedule & PIK Toggle
B14: 4. Free Cash Flow
B15: 5. Returns & Fee Waterfall
B16: 6. Sensitivity Analysis
... B25: Prepared by: Alessandro Radice · March 2026 · Fictional case study, all data hypothetical

Sheet Assumptions
A1: ASSUMPTIONS & SOURCES / USES | C1: Y1 | D1: Y2 | E1: Y3 | F1: Y4 | G1: Y5
A3: SCENARIO CONTROL
A4: Active Scenario (1 = Downside · 2 = Base · 3 = Upside) | C4: 2
A5: Active Scenario | C5: =CHOOSE(C4,"Downside","Base","Upside") -> Base
A6: Revenue Growth by Scenario | C6: Y1 | D6: Y2 | E6: Y3 | F6: Y4 | G6: Y5
A7: Downside | C7: 0.15 | D7: 0.13 | E7: 0.11 | F7: 0.09 | G7: 0.08
A8: Base | C8: 0.22 | D8: 0.19 | E8: 0.16 | F8: 0.13 | G8: 0.11
A9: Upside | C9: 0.22 | D9: 0.22 | E9: 0.22 | F9: 0.22 | G9: 0.22
A10: Active Growth Path | C10: =INDEX(C7:C9,$C$4) -> 0.22 | D10: =INDEX(D7:D9,$C$4) -> 0.19 | E10: =INDEX(E7:E9,$C$4) -> 0.16 | F10: =INDEX(F7:F9,$C$4) -> 0.13 | G10: =INDEX(G7:G9,$C$4) -> 0.11
A11: Exit EV/EBITDA by Scenario (D / B / U) | C11: 13 | D11: 15 | E11: 16
A12: Active Exit EV/EBITDA | C12: =CHOOSE($C$4,C11,D11,E11) -> 15
A14: TRANSACTION ASSUMPTIONS
A15: Entry Year | C15: 2026
A16: Hold Period (years) | C16: 5
A17: Entry EV / LTM EBITDA | C17: 18.5
A18: Exit EV / LTM EBITDA (active scenario) | C18: =C12 -> 15
A19: LTM EBITDA ($mm) | C19: 26.2
A20: Entry Enterprise Value ($mm) | C20: =C17*C19 -> 484.7
A21: Total Debt (55% EV) | C21: =C20*0.55 -> 266.585
A23: OPERATING ASSUMPTIONS
A24: LTM Revenue ($mm) | C24: 48
A25: LTM EBITDA Margin | C25: 0.545
A26: EBITDA Margin Expansion / yr | C26: 0.006
A27: D&A as % Revenue | C27: 0.03
A28: CapEx as % Revenue | C28: 0.025
A29: Change in NWC as % Rev Δ | C29: -0.05
A30: Cash Tax Rate | C30: 0.25
A31: SOFR (floating base rate) | C31: 0.053
A32: TLB Spread (bps over SOFR) | C32: 0.035
A33: TLB All-In Rate (SOFR + Spread) | C33: =C31+C32 -> 0.088
A34: Unitranche Rate (fixed) | C34: 0.085
A35: PIK Notes Rate (accretes) | C35: 0.085
A37: SOURCES & USES ($mm)
A38: USES
A39: Purchase Enterprise Value | C39: =C20 -> 484.7
A40: Transaction Fees (2.0%) | C40: =C20*0.02 -> 9.694
A41: Financing Fees (1.5%) | C41: =C20*0.015 -> 7.2705
A42: Total Uses | C42: =SUM(C39:C41) -> 501.6645
A43: SOURCES
A44: Term Loan B (35% EV · SOFR+350) | C44: =C20*0.35 -> 169.645
...

Sheet Income Stmt
A1: INCOME STATEMENT ($mm) | B1: LTM | C1: Year 1 | D1: Year 2 | E1: Year 3 | F1: Year 4 | G1: Year 5
A2: REVENUE
A3: Subscription (ARR) | B3: 40.8 | C3: =B3*(1+Assumptions!C$10) -> 49.776 | D3: =C3*(1+Assumptions!D$10) -> 59.23344 | E3: =D3*(1+Assumptions!E$10) -> 68.71079 | F3: =E3*(1+Assumptions!F$10) -> 77.643193 | G3: =F3*(1+Assumptions!G$10) -> 86.183944
A4: Professional Services | B4: 4.8 | C4: =B4*(1+Assumptions!C$10) -> 5.856 | D4: =C4*(1+Assumptions!D$10) -> 6.96864 | E4: =D4*(1+Assumptions!E$10) -> 8.0836224 | F4: =E4*(1+Assumptions!F$10) -> 9.1344933 | G4: =F4*(1+Assumptions!G$10) -> 10.139288
A5: Other | B5: 2.4 | C5: =B5*(1+Assumptions!C$10) -> 2.928 | D5: =C5*(1+Assumptions!D$10) -> 3.48432 | E5: =D5*(1+Assumptions!E$10) -> 4.0418112 | F5: =E5*(1+Assumptions!F$10) -> 4.5672467 | G5: =F5*(1+Assumptions!G$10) -> 5.0696438
A6: Total Revenue | B6: =SUM(B3:B5) -> 48 | C6: =SUM(C3:C5) -> 58.56 | D6: =SUM(D3:D5) -> 69.6864 | E6: =SUM(E3:E5) -> 80.836224 | F6: =SUM(F3:F5) -> 91.344933 | G6: =SUM(G3:G5) -> 101.39288
A7: EBITDA BRIDGE
A8: Gross Profit (82%) | B8: =B6*0.82 -> 39.36 | C8: =C6*0.82 -> 48.0192 | D8: =D6*0.82 -> 57.142848 | E8: =E6*0.82 -> 66.285704 | F8: =F6*0.82 -> 74.902845 | G8: =G6*0.82 -> 83.142158
A9: S&M Expense (12%) | B9: =-B6*0.12 -> -5.76 | C9: =-C6*0.12 -> -7.0272 | D9: =-D6*0.12 -> -8.362368 | E9: =-E6*0.12 -> -9.7003469 | F9: =-F6*0.12 -> -10.961392 | G9: =-G6*0.12 -> -12.167145
A10: R&D Expense (10%) | B10: =-B6*0.1 -> -4.8 | C10: =-C6*0.1 -> -5.856 | D10: =-D6*0.1 -> -6.96864 | E10: =-E6*0.1 -> -8.0836224 | F10: =-F6*0.1 -> -9.1344933 | G10: =-G6*0.1 -> -10.139288
A11: G&A Expense (implied / balancing) | B11: =B12-B8-B9-B10 -> -2.64 | C11: =C12-C8-C9-C10 -> -2.86944 | D11: =D12-D8-D9-D10 -> -2.9965152 | E11: =E12-E8-E9-E10 -> -2.9909403 | F11: =F12-F8-F9-F10 -> -2.8316929 | G11: =G12-G8-G9-G10 -> -2.5348219
A12: EBITDA | B12: =B6*B13 -> 26.16 | C12: =C6*C13 -> 32.26656 | D12: =D6*D13 -> 38.815325 | E12: =E6*E13 -> 45.510794 | F12: =F6*F13 -> 51.975267 | G12: =G6*G13 -> 58.300904
A13: EBITDA Margin | B13: =Assumptions!$C$25 -> 0.545 | C13: =B13+Assumptions!$C$26 -> 0.551 | D13: =C13+Assumptions!$C$26 -> 0.557 | E13: =D13+Assumptions!$C$26 -> 0.563 | F13: =E13+Assumptions!$C$26 -> 0.569 | G13: =F13+Assumptions!$C$26 -> 0.575
A14: BELOW-THE-LINE
A15: D&A | B15: =-B6*Assumptions!$C$27 -> -1.44 | C15: =-C6*Assumptions!$C$27 -> -1.7568 | D15: =-D6*Assumptions!$C$27 -> -2.090592 | E15: =-E6*Assumptions!$C$27 -> -2.4250867 | F15: =-F6*Assumptions!$C$27 -> -2.740348 | G15: =-G6*Assumptions!$C$27 -> -3.0417863
A16: EBIT | B16: =B12+B15 -> 24.72 | C16: =C12+C15 -> 30.50976 | D16: =D12+D15 -> 36.724733 | E16: =E12+E15 -> 43.085707 | F16: =F12+F15 -> 49.234919 | G16: =G12+G15 -> 55.259117
A17: Cash Interest | B17: 0 | C17: ='Debt Schedule'!C19 -> -21.108685 | D17: ='Debt Schedule'!D19 -> -20.463592 | E17: ='Debt Schedule'!E19 -> -19.359479 | F17: ='Debt Schedule'!F19 -> -17.753689 | G17: ='Debt Schedule'!G19 -> -15.624088
A18: PIK Accrual | B18: 0 | C18: =-'Debt Schedule'!C20 -> -2.059975 | D18: =-'Debt Schedule'!D20 -> -2.2350729 | E18: =-'Debt Schedule'!E20 -> -2.4250541 | F18: =-'Debt Schedule'!F20 -> -2.6311837 | G18: =-'Debt Schedule'!G20 -> -2.8548343
A19: EBT (pre-tax) | B19: =B16+B17+B18 -> 24.72 | C19: =C16+C17+C18 -> 7.3411 | D19: =D16+D17+D18 -> 14.026068 | E19: =E16+E17+E18 -> 21.301174 | F19: =F16+F17+F18 -> 28.850047 | G19: =G16+G17+G18 -> 36.780195
A20: Cash Taxes | B20: =IF(B19>0,-B19*Assumptions!$C$30,0) -> -6.18 | C20: =IF(C19>0,-C19*Assumptions!$C$30,0) -> -1.835275 | D20: =IF(D19>0,-D19*Assumptions!$C$30,0) -> -3.5065169 | E20: =IF(E19>0,-E19*Assumptions!$C$30,0) -> -5.3252935 | F20: =IF(F19>0,-F19*Assumptions!$C$30,0) -> -7.2125117 | G20: =IF(G19>0,-G19*Assumptions!$C$30,0) -> -9.1950488
A21: Net Income | B21: =B19+B20 -> 18.54 | C21: =C19+C20 -> 5.505825 | D21: =D19+D20 -> 10.519551 | E21: =E19+E20 -> 15.97588 | F21: =F19+F20 -> 21.637535 | G21: =G19+G20 -> 27.585146
A22: Revenue Growth YoY | C22: =(C6-B6)/B6 -> 0.22 | D22: =(D6-C6)/C6 -> 0.19 | E22: =(E6-D6)/D6 -> 0.16 | F22: =(F6-E6)/E6 -> 0.13 | G22: =(G6-F6)/F6 -> 0.11

Sheet Debt Schedule
A1: DEBT SCHEDULE & PIK TOGGLE ($mm) | B1: Entry | C1: Year 1 | D1: Year 2 | E1: Year 3 | F1: Year 4 | G1: Year 5
A2: TERM LOAN B (SOFR + 350bps · 1% amort + cash sweep)
A3: Opening Balance | B3: =Assumptions!C44 -> 169.645 | C3: =B6 -> 169.645 | D3: =C6 -> 162.3144 | E3: =D6 -> 149.76766 | F3: =E6 -> 131.52004 | G3: =F6 -> 107.32003
A4: Mandatory Amortisation (1%) | B4: 0 | C4: =-MIN(0.01*Assumptions!$C$44,C3) -> -1.69645 | D4: =-MIN(0.01*Assumptions!$C$44,D3) -> -1.69645 | E4: =-MIN(0.01*Assumptions!$C$44,E3) -> -1.69645 | F4: =-MIN(0.01*Assumptions!$C$44,F3) -> -1.69645 | G4: =-MIN(0.01*Assumptions!$C$44,G3) -> -1.69645
A5: Cash Sweep (100% excess FCF) | B5: 0 | C5: =-MAX(MIN(FCF!C12+C4,C3+C4),0) -> -5.63415 | D5: =-MAX(MIN(FCF!D12+D4,D3+D4),0) -> -10.850286 | E5: =-MAX(MIN(FCF!E12+E4,E3+E4),0) -> -16.551174 | F5: =-MAX(MIN(FCF!F12+F4,F3+F4),0) -> -22.503558 | G5: =-MAX(MIN(FCF!G12+G4,G3+G4),0) -> -28.748098
A6: Closing Balance | B6: =B3+B4+B5 -> 169.645 | C6: =C3+C4+C5 -> 162.3144 | D6: =D3+D4+D5 -> 149.76766 | E6: =E3+E4+E5 -> 131.52004 | F6: =F3+F4+F5 -> 107.32003 | G6: =G3+G4+G5 -> 76.875484
A7: Cash Interest (opening basis) | B7: 0 | C7: =-C3*Assumptions!$C$33 -> -14.92876 | D7: =-D3*Assumptions!$C$33 -> -14.283667 | E7: =-E3*Assumptions!$C$33 -> -13.179554 | F7: =-F3*Assumptions!$C$33 -> -11.573764 | G7: =-G3*Assumptions!$C$33 -> -9.4441628
A9: UNITRANCHE (8.5% Fixed · bullet)
A10: Opening Balance (bullet) | B10: =Assumptions!C45 -> 72.705 | C10: =B10 -> 72.705 | D10: =C10 -> 72.705 | E10: =D10 -> 72.705 | F10: =E10 -> 72.705 | G10: =F10 -> 72.705
A11: Cash Interest | B11: 0 | C11: =-C10*Assumptions!$C$34 -> -6.179925 | D11: =-D10*Assumptions!$C$34 -> -6.179925 | E11: =-E10*Assumptions!$C$34 -> -6.179925 | F11: =-F10*Assumptions!$C$34 -> -6.179925 | G11: =-G10*Assumptions!$C$34 -> -6.179925
A13: PIK NOTES (8.5% · Toggle · accretes)
A14: Opening Balance | B14: =Assumptions!C46 -> 24.235 | C14: =B16 -> 24.235 | D14: =C16 -> 26.294975 | E14: =D16 -> 28.530048 | F14: =E16 -> 30.955102 | G14: =F16 -> 33.586286
A15: PIK Accrual (8.5% on opening) | B15: 0 | C15: =C14*Assumptions!$C$35 -> 2.059975 | D15: =D14*Assumptions!$C$35 -> 2.2350729 | E15: =E14*Assumptions!$C$35 -> 2.4250541 | F15: =F14*Assumptions!$C$35 -> 2.6311837 | G15: =G14*Assumptions!$C$35 -> 2.8548343
A16: Closing Balance | B16: =B14+B15 -> 24.235 | C16: =C14+C15 -> 26.294975 | D16: =D14+D15 -> 28.530048 | E16: =E14+E15 -> 30.955102 | F16: =F14+F15 -> 33.586286 | G16: =G14+G15 -> 36.44112
A18: TOTALS
A19: Total Cash Interest | B19: =B7+B11 -> 0 | C19: =C7+C11 -> -21.108685 | D19: =D7+D11 -> -20.463592 | E19: =E7+E11 -> -19.359479 | F19: =F7+F11 -> -17.753689 | G19: =G7+G11 -> -15.624088
A20: Total PIK Accrual | B20: =B15 -> 0 | C20: =C15 -> 2.059975 | D20: =D15 -> 2.2350729 | E20: =E15 -> 2.4250541 | F20: =F15 -> 2.6311837 | G20: =G15 -> 2.8548343
A21: Total Debt (net) | B21: =B6+B10+B16 -> 266.585 | C21: =C6+C10+C16 -> 261.31437 | D21: =D6+D10+D16 -> 251.00271 | E21: =E6+E10+E16 -> 235.18014 | F21: =F6+F10+F16 -> 213.61132 | G21: =G6+G10+G16 -> 186.0216
A22: Net Leverage (x EBITDA) | B22: =B21/'Income Stmt'!B12 -> 10.190558 | C22: =C21/'Income Stmt'!C12 -> 8.0986128 | D22: =D21/'Income Stmt'!D12 -> 6.466588 | E22: =E21/'Income Stmt'!E12 -> 5.1675684 | F22: =F21/'Income Stmt'!F12 -> 4.1098648 | G22: =G21/'Income Stmt'!G12 -> 3.1907156

Sheet FCF
A1: FREE CASH FLOW ($mm) | B1: Entry | C1: Year 1 | D1: Year 2 | E1: Year 3 | F1: Year 4 | G1: Year 5
A2: UNLEVERED FREE CASH FLOW
A3: EBITDA | B3: ='Income Stmt'!B12 -> 26.16 | C3: ='Income Stmt'!C12 -> 32.26656 | D3: ='Income Stmt'!D12 -> 38.815325 | E3: ='Income Stmt'!E12 -> 45.510794 | F3: ='Income Stmt'!F12 -> 51.975267 | G3: ='Income Stmt'!G12 -> 58.300904
A4: Less: CapEx | B4: =-'Income Stmt'!B6*Assumptions!$C$28 -> -1.2 | C4: =-'Income Stmt'!C6*Assumptions!$C$28 -> -1.464 | D4: =-'Income Stmt'!D6*Assumptions!$C$28 -> -1.74216 | E4: =-'Income Stmt'!E6*Assumptions!$C$28 -> -2.0209056 | F4: =-'Income Stmt'!F6*Assumptions!$C$28 -> -2.2836233 | G4: =-'Income Stmt'!G6*Assumptions!$C$28 -> -2.5348219
A5: Change in NWC | B5: 0 | C5: =('Income Stmt'!C6-'Income Stmt'!B6)*Assumptions!$C$29 -> -0.528 | D5: =('Income Stmt'!D6-'Income Stmt'!C6)*Assumptions!$C$29 -> -0.55632 | E5: =('Income Stmt'!E6-'Income Stmt'!D6)*Assumptions!$C$29 -> -0.5574912 | F5: =('Income Stmt'!F6-'Income Stmt'!E6)*Assumptions!$C$29 -> -0.52543546 | G5: =('Income Stmt'!G6-'Income Stmt'!F6)*Assumptions!$C$29 -> -0.50239713
A6: Less: Cash Taxes | B6: ='Income Stmt'!B20 -> -6.18 | C6: ='Income Stmt'!C20 -> -1.835275 | D6: ='Income Stmt'!D20 -> -3.5065169 | E6: ='Income Stmt'!E20 -> -5.3252935 | F6: ='Income Stmt'!F20 -> -7.2125117 | G6: ='Income Stmt'!G20 -> -9.1950488
A7: Unlevered FCF | B7: =SUM(B3:B6) -> 18.78 | C7: =SUM(C3:C6) -> 28.439285 | D7: =SUM(D3:D6) -> 33.010328 | E7: =SUM(E3:E6) -> 37.607104 | F7: =SUM(F3:F6) -> 41.953696 | G7: =SUM(G3:G6) -> 46.068636
A9: LEVERED FCF & DEBT SERVICE
A10: Unlevered FCF | B10: =B7 -> 18.78 | C10: =C7 -> 28.439285 | D10: =D7 -> 33.010328 | E10: =E7 -> 37.607104 | F10: =F7 -> 41.953696 | G10: =G7 -> 46.068636
A11: Less: Cash Interest | B11: ='Debt Schedule'!B19 -> 0 | C11: ='Debt Schedule'!C19 -> -21.108685 | D11: ='Debt Schedule'!D19 -> -20.463592 | E11: ='Debt Schedule'!E19 -> -19.359479 | F11: ='Debt Schedule'!F19 -> -17.753689 | G11: ='Debt Schedule'!G19 -> -15.624088
A12: Levered FCF (cash for debt service) | B12: =B10+B11 -> 18.78 | C12: =C10+C11 -> 7.3306 | D12: =D10+D11 -> 12.546736 | E12: =E10+E11 -> 18.247624 | F12: =F10+F11 -> 24.200008 | G12: =G10+G11 -> 30.444548
A13: Less: Mandatory Amortisation | B13: ='Debt Schedule'!B4 -> 0 | C13: ='Debt Schedule'!C4 -> -1.69645 | D13: ='Debt Schedule'!D4 -> -1.69645 | E13: ='Debt Schedule'!E4 -> -1.69645 | F13: ='Debt Schedule'!F4 -> -1.69645 | G13: ='Debt Schedule'!G4 -> -1.69645
A14: Less: Cash Sweep | B14: ='Debt Schedule'!B5 -> 0 | C14: ='Debt Schedule'!C5 -> -5.63415 | D14: ='Debt Schedule'!D5 -> -10.850286 | E14: ='Debt Schedule'!E5 -> -16.551174 | F14: ='Debt Schedule'!F5 -> -22.503558 | G14: ='Debt Schedule'!G5 -> -28.748098
A15: Net Cash Flow (to balance sheet) | B15: =B12+B13+B14 -> 18.78 | C15: =C12+C13+C14 -> 0 | D15: =D12+D13+D14 -> 0 | E15: =E12+E13+E14 -> 0 | F15: =F12+F13+F14 -> 0 | G15: =G12+G13+G14 -> 0

Sheet Returns
A1: RETURNS ANALYSIS & FEE WATERFALL
A2: EXIT ASSUMPTIONS
A3: Hold Period (years) | B3: =Assumptions!C16 -> 5
A4: Exit EBITDA ($mm) | B4: ='Income Stmt'!G12 -> 58.300904
A5: Exit EV / EBITDA (active) | B5: =Assumptions!C18 -> 15
A6: Exit Enterprise Value ($mm) | B6: =B4*B5 -> 874.51355
A7: Less: Net Debt at Exit | B7: =-'Debt Schedule'!G21 -> -186.0216
A8: Total Exit Equity ($mm) | B8: =B6+B7 -> 688.49195
A9: Sponsor Ownership % (excl. rollover & MIP) | B9: =Assumptions!C48/(Assumptions!C48+Assumptions!C47) -> 0.93814433
A10: Sponsor Exit Equity ($mm) | B10: =B8*B9 -> 645.90482
A12: RETURN METRICS | D12: Benchmark
A13: Invested Equity: Sponsor ($mm) | B13: =Assumptions!C48 -> 220.5385 | D13: –
A14: Sponsor Exit Equity ($mm) | B14: =B10 -> 645.90482 | D14: –
A15: Gross MoM | B15: =B14/B13 -> 2.9287622 | D15: >2.5x
A16: Gross IRR | B16: =(B14/B13)^(1/B3)-1 -> 0.23975772 | D16: >20%
A17: LP Net Proceeds ($mm) | B17: =B24+B25+B27 -> 560.83155 | D17: –
A18: Net MoM (post pref & carry) | B18: =B17/B13 -> 2.5430097 | D18: >2.0x
A19: Net IRR (post pref & carry) | B19: =(B17/B13)^(1/B3)-1 -> 0.20522909 | D19: >15%
A20: GP Carried Interest ($mm) | B20: =B26+B28 -> 85.073264 | D20: 20% of profit
A22: FEE WATERFALL (on sponsor proceeds)
A23: Tier | B23: Amount ($mm) | C23: % Equity | D23: Recipient | E23: Notes
A24: Return of Capital | B24: =B13 -> 220.5385 | C24: =B24/$B$10 -> 0.34144117 | D24: LP | E24: Entry equity returned first
A25: Preferred Return 8% p.a. | B25: =B13*(1.08^B3)-B13 -> 103.50491 | C25: =B25/$B$10 -> 0.16024793 | D25: LP | E25: Compounded over hold
A26: GP Catch-Up (20%) | B26: =B25*0.2/0.8 -> 25.876228 | C26: =B26/$B$10 -> 0.040061982 | D26: GP | E26: Full catch-up on preferred
A27: LP 80% Residual | B27: =(B10-B24-B25-B26)*0.8 -> 236.78814 | C27: =B27/$B$10 -> 0.36659913 | D27: LP | E27: Post catch-up
A28: GP Carried Interest 20% | B28: =(B10-B24-B25-B26)*0.2 -> 59.197036 | C28: =B28/$B$10 -> 0.091649783 | D28: GP | E28: 20% carry on profit
A29: TOTAL = Sponsor Exit Equity | B29: =SUM(B24:B28) -> 645.90482 | C29: =B29/$B$10 -> 1

Sheet Sensitivity
A1: SENSITIVITY ANALYSIS: IRR & MoM
A2: GROSS IRR: Entry Multiple (rows) × Exit Multiple (cols)
A3: Entry ↓ / Exit → | B3: 13.0x | C3: 14.0x | D3: 15.0x | E3: 16.0x | F3: 17.0x
A4: 16.5x | B4: =((('Income Stmt'!$G$12*VALUE(SUBSTITUTE(B$3,"x",""))-'Debt Schedule'!$G$21*(VALUE(SUBSTITUTE($A4,"x",""))/Assumptions!$C$17))*Returns!$B$9)/(Returns!$B$13*(VALUE(SUBSTITUTE($A4,"x",""))/Assumptions!$C$17)))^(1/Assumptions!$C$16)-1 -> 0.23071936 | C4: =((('Income Stmt'!$G$12*VALUE(SUBSTITUTE(C$3,"x",""))-'Debt Schedule'!$G$21*(VALUE(SUBSTITUTE($A4,"x",""))/Assumptions!$C$17))*Returns!$B$9)/(Returns!$B$13*(VALUE(SUBSTITUTE($A4,"x",""))/Assumptions!$C$17)))^(1/Assumptions!$C$16)-1 -> 0.2540578 | D4: =((('Income Stmt'!$G$12*VALUE(SUBSTITUTE(D$3,"x",""))-'Debt Schedule'!$G$21*(VALUE(SUBSTITUTE($A4,"x",""))/Assumptions!$C$17))*Returns!$B$9)/(Returns!$B$13*(VALUE(SUBSTITUTE($A4,"x",""))/Assumptions!$C$17)))^(1/Assumptions!$C$16)-1 -> 0.27577806 | E4: =((('Income Stmt'!$G$12*VALUE(SUBSTITUTE(E$3,"x",""))-'Debt Schedule'!$G$21*(VALUE(SUBSTITUTE($A4,"x",""))/Assumptions!$C$17))*Returns!$B$9)/(Returns!$B$13*(VALUE(SUBSTITUTE($A4,"x",""))/Assumptions!$C$17)))^(1/Assumptions!$C$16)-1 -> 0.29611258 | F4: =((('Income Stmt'!$G$12*VALUE(SUBSTITUTE(F$3,"x",""))-'Debt Schedule'!$G$21*(VALUE(SUBSTITUTE($A4,"x",""))/Assumptions!$C$17))*Returns!$B$9)/(Returns!$B$13*(VALUE(SUBSTITUTE($A4,"x",""))/Assumptions!$C$17)))^(1/Assumptions!$C$16)-1 -> 0.3152457
A5: 17.5x | B5: =((('Income Stmt'!$G$12*VALUE(SUBSTITUTE(B$3,"x",""))-'Debt Schedule'!$G$21*(VALUE(SUBSTITUTE($A5,"x",""))/Assumptions!$C$17))*Returns!$B$9)/(Returns!$B$13*(VALUE(SUBSTITUTE($A5,"x",""))/Assumptions!$C$17)))^(1/Assumptions!$C$16)-1 -> 0.21216078 | C5: =((('Income Stmt'!$G$12*VALUE(SUBSTITUTE(C$3,"x",""))-'Debt Schedule'!$G$21*(VALUE(SUBSTITUTE($A5,"x",""))/Assumptions!$C$17))*Returns!$B$9)/(Returns!$B$13*(VALUE(SUBSTITUTE($A5,"x",""))/Assumptions!$C$17)))^(1/Assumptions!$C$16)-1 -> 0.23552972 | D5: =((('Income Stmt'!$G$12*VALUE(SUBSTITUTE(D$3,"x",""))-'Debt Schedule'!$G$21*(VALUE(SUBSTITUTE($A5,"x",""))/Assumptions!$C$17))*Returns!$B$9)/(Returns!$B$13*(VALUE(SUBSTITUTE($A5,"x",""))/Assumptions!$C$17)))^(1/Assumptions!$C$16)-1 -> 0.25725373 | E5: =((('Income Stmt'!$G$12*VALUE(SUBSTITUTE(E$3,"x",""))-'Debt Schedule'!$G$21*(VALUE(SUBSTITUTE($A5,"x",""))/Assumptions!$C$17))*Returns!$B$9)/(Returns!$B$13*(VALUE(SUBSTITUTE($A5,"x",""))/Assumptions!$C$17)))^(1/Assumptions!$C$16)-1 -> 0.27757242 | F5: =((('Income Stmt'!$G$12*VALUE(SUBSTITUTE(F$3,"x",""))-'Debt Schedule'!$G$21*(VALUE(SUBSTITUTE($A5,"x",""))/Assumptions!$C$17))*Returns!$B$9)/(Returns!$B$13*(VALUE(SUBSTITUTE($A5,"x",""))/Assumptions!$C$17)))^(1/Assumptions!$C$16)-1 -> 0.29667513
A6: 18.5x | B6: =((('Income Stmt'!$G$12*VALUE(SUBSTITUTE(B$3,"x",""))-'Debt Schedule'!$G$21*(VALUE(SUBSTITUTE($A6,"x",""))/Assumptions!$C$17))*Returns!$B$9)/(Returns!$B$13*(VALUE(SUBSTITUTE($A6,"x",""))/Assumptions!$C$17)))^(1/Assumptions!$C$16)-1 -> 0.19459191 | C6: =((('Income Stmt'!$G$12*VALUE(SUBSTITUTE(C$3,"x",""))-'Debt Schedule'!$G$21*(VALUE(SUBSTITUTE($A6,"x",""))/Assumptions!$C$17))*Returns!$B$9)/(Returns!$B$13*(VALUE(SUBSTITUTE($A6,"x",""))/Assumptions!$C$17)))^(1/Assumptions!$C$16)-1 -> 0.2180118 | D6: =((('Income Stmt'!$G$12*VALUE(SUBSTITUTE(D$3,"x",""))-'Debt Schedule'!$G$21*(VALUE(SUBSTITUTE($A6,"x",""))/Assumptions!$C$17))*Returns!$B$9)/(Returns!$B$13*(VALUE(SUBSTITUTE($A6,"x",""))/Assumptions!$C$17)))^(1/Assumptions!$C$16)-1 -> 0.23975772 | E6: =((('Income Stmt'!$G$12*VALUE(SUBSTITUTE(E$3,"x",""))-'Debt Schedule'!$G$21*(VALUE(SUBSTITUTE($A6,"x",""))/Assumptions!$C$17))*Returns!$B$9)/(Returns!$B$13*(VALUE(SUBSTITUTE($A6,"x",""))/Assumptions!$C$17)))^(1/Assumptions!$C$16)-1 -> 0.26007698 | F6: =((('Income Stmt'!$G$12*VALUE(SUBSTITUTE(F$3,"x",""))-'Debt Schedule'!$G$21*(VALUE(SUBSTITUTE($A6,"x",""))/Assumptions!$C$17))*Returns!$B$9)/(Returns!$B$13*(VALUE(SUBSTITUTE($A6,"x",""))/Assumptions!$C$17)))^(1/Assumptions!$C$16)-1 -> 0.27916433
A7: 19.5x | B7: =((('Income Stmt'!$G$12*VALUE(SUBSTITUTE(B$3,"x",""))-'Debt Schedule'!$G$21*(VALUE(SUBSTITUTE($A7,"x",""))/Assumptions!$C$17))*Returns!$B$9)/(Returns!$B$13*(VALUE(SUBSTITUTE($A7,"x",""))/Assumptions!$C$17)))^(1/Assumptions!$C$16)-1 -> 0.17789402 | C7: =((('Income Stmt'!$G$12*VALUE(SUBSTITUTE(C$3,"x",""))-'Debt Schedule'!$G$21*(VALUE(SUBSTITUTE($A7,"x",""))/Assumptions!$C$17))*Returns!$B$9)/(Returns!$B$13*(VALUE(SUBSTITUTE($A7,"x",""))/Assumptions!$C$17)))^(1/Assumptions!$C$16)-1 -> 0.20138398 | D7: =((('Income Stmt'!$G$12*VALUE(SUBSTITUTE(D$3,"x",""))-'Debt Schedule'!$G$21*(VALUE(SUBSTITUTE($A7,"x",""))/Assumptions!$C$17))*Returns!$B$9)/(Returns!$B$13*(VALUE(SUBSTITUTE($A7,"x",""))/Assumptions!$C$17)))^(1/Assumptions!$C$16)-1 -> 0.22316865 | E7: =((('Income Stmt'!$G$12*VALUE(SUBSTITUTE(E$3,"x",""))-'Debt Schedule'!$G$21*(VALUE(SUBSTITUTE($A7,"x",""))/Assumptions!$C$17))*Returns!$B$9)/(Returns!$B$13*(VALUE(SUBSTITUTE($A7,"x",""))/Assumptions!$C$17)))^(1/Assumptions!$C$16)-1 -> 0.24350359 | F7: =((('Income Stmt'!$G$12*VALUE(SUBSTITUTE(F$3,"x",""))-'Debt Schedule'!$G$21*(VALUE(SUBSTITUTE($A7,"x",""))/Assumptions!$C$17))*Returns!$B$9)/(Returns!$B$13*(VALUE(SUBSTITUTE($A7,"x",""))/Assumptions!$C$17)))^(1/Assumptions!$C$16)-1 -> 0.26258931
A8: 20.5x | B8: =((('Income Stmt'!$G$12*VALUE(SUBSTITUTE(B$3,"x",""))-'Debt Schedule'!$G$21*(VALUE(SUBSTITUTE($A8,"x",""))/Assumptions!$C$17))*Returns!$B$9)/(Returns!$B$13*(VALUE(SUBSTITUTE($A8,"x",""))/Assumptions!$C$17)))^(1/Assumptions!$C$16)-1 -> 0.16196692 | C8: =((('Income Stmt'!$G$12*VALUE(SUBSTITUTE(C$3,"x",""))-'Debt Schedule'!$G$21*(VALUE(SUBSTITUTE($A8,"x",""))/Assumptions!$C$17))*Returns!$B$9)/(Returns!$B$13*(VALUE(SUBSTITUTE($A8,"x",""))/Assumptions!$C$17)))^(1/Assumptions!$C$16)-1 -> 0.18554506 | D8: =((('Income Stmt'!$G$12*VALUE(SUBSTITUTE(D$3,"x",""))-'Debt Schedule'!$G$21*(VALUE(SUBSTITUTE($A8,"x",""))/Assumptions!$C$17))*Returns!$B$9)/(Returns!$B$13*(VALUE(SUBSTITUTE($A8,"x",""))/Assumptions!$C$17)))^(1/Assumptions!$C$16)-1 -> 0.20738425 | E8: =((('Income Stmt'!$G$12*VALUE(SUBSTITUTE(E$3,"x",""))-'Debt Schedule'!$G$21*(VALUE(SUBSTITUTE($A8,"x",""))/Assumptions!$C$17))*Returns!$B$9)/(Returns!$B$13*(VALUE(SUBSTITUTE($A8,"x",""))/Assumptions!$C$17)))^(1/Assumptions!$C$16)-1 -> 0.22774889 | F8: =((('Income Stmt'!$G$12*VALUE(SUBSTITUTE(F$3,"x",""))-'Debt Schedule'!$G$21*(VALUE(SUBSTITUTE($A8,"x",""))/Assumptions!$C$17))*Returns!$B$9)/(Returns!$B$13*(VALUE(SUBSTITUTE($A8,"x",""))/Assumptions!$C$17)))^(1/Assumptions!$C$16)-1 -> 0.24684569
A10: MONEY-ON-MONEY: Entry × Exit
A11: Entry ↓ / Exit → | B11: 13.0x | C11: 14.0x | D11: 15.0x | E11: 16.0x | F11: 17.0x
A12: 16.5x | B12: =(('Income Stmt'!$G$12*VALUE(SUBSTITUTE(B$11,"x",""))-'Debt Schedule'!$G$21*(VALUE(SUBSTITUTE($A12,"x",""))/Assumptions!$C$17))*Returns!$B$9)/(Returns!$B$13*(VALUE(SUBSTITUTE($A12,"x",""))/Assumptions!$C$17)) -> 2.8235479 | C12: =(('Income Stmt'!$G$12*VALUE(SUBSTITUTE(C$11,"x",""))-'Debt Schedule'!$G$21*(VALUE(SUBSTITUTE($A12,"x",""))/Assumptions!$C$17))*Returns!$B$9)/(Returns!$B$13*(VALUE(SUBSTITUTE($A12,"x",""))/Assumptions!$C$17)) -> 3.1016142 | D12: =(('Income Stmt'!$G$12*VALUE(SUBSTITUTE(D$11,"x",""))-'Debt Schedule'!$G$21*(VALUE(SUBSTITUTE($A12,"x",""))/Assumptions!$C$17))*Returns!$B$9)/(Returns!$B$13*(VALUE(SUBSTITUTE($A12,"x",""))/Assumptions!$C$17)) -> 3.3796805 | E12: =(('Income Stmt'!$G$12*VALUE(SUBSTITUTE(E$11,"x",""))-'Debt Schedule'!$G$21*(VALUE(SUBSTITUTE($A12,"x",""))/Assumptions!$C$17))*Returns!$B$9)/(Returns!$B$13*(VALUE(SUBSTITUTE($A12,"x",""))/Assumptions!$C$17)) -> 3.6577467 | F12: =(('Income Stmt'!$G$12*VALUE(SUBSTITUTE(F$11,"x",""))-'Debt Schedule'!$G$21*(VALUE(SUBSTITUTE($A12,"x",""))/Assumptions!$C$17))*Returns!$B$9)/(Returns!$B$13*(VALUE(SUBSTITUTE($A12,"x",""))/Assumptions!$C$17)) -> 3.935813
A13: 17.5x | B13: =(('Income Stmt'!$G$12*VALUE(SUBSTITUTE(B$11,"x",""))-'Debt Schedule'!$G$21*(VALUE(SUBSTITUTE($A13,"x",""))/Assumptions!$C$17))*Returns!$B$9)/(Returns!$B$13*(VALUE(SUBSTITUTE($A13,"x",""))/Assumptions!$C$17)) -> 2.6169844 | C13: =(('Income Stmt'!$G$12*VALUE(SUBSTITUTE(C$11,"x",""))-'Debt Schedule'!$G$21*(VALUE(SUBSTITUTE($A13,"x",""))/Assumptions!$C$17))*Returns!$B$9)/(Returns!$B$13*(VALUE(SUBSTITUTE($A13,"x",""))/Assumptions!$C$17)) -> 2.8791612 | D13: =(('Income Stmt'!$G$12*VALUE(SUBSTITUTE(D$11,"x",""))-'Debt Schedule'!$G$21*(VALUE(SUBSTITUTE($A13,"x",""))/Assumptions!$C$17))*Returns!$B$9)/(Returns!$B$13*(VALUE(SUBSTITUTE($A13,"x",""))/Assumptions!$C$17)) -> 3.1413379 | E13: =(('Income Stmt'!$G$12*VALUE(SUBSTITUTE(E$11,"x",""))-'Debt Schedule'!$G$21*(VALUE(SUBSTITUTE($A13,"x",""))/Assumptions!$C$17))*Returns!$B$9)/(Returns!$B$13*(VALUE(SUBSTITUTE($A13,"x",""))/Assumptions!$C$17)) -> 3.4035147 | F13: =(('Income Stmt'!$G$12*VALUE(SUBSTITUTE(F$11,"x",""))-'Debt Schedule'!$G$21*(VALUE(SUBSTITUTE($A13,"x",""))/Assumptions!$C$17))*Returns!$B$9)/(Returns!$B$13*(VALUE(SUBSTITUTE($A13,"x",""))/Assumptions!$C$17)) -> 3.6656915
A14: 18.5x | B14: =(('Income Stmt'!$G$12*VALUE(SUBSTITUTE(B$11,"x",""))-'Debt Schedule'!$G$21*(VALUE(SUBSTITUTE($A14,"x",""))/Assumptions!$C$17))*Returns!$B$9)/(Returns!$B$13*(VALUE(SUBSTITUTE($A14,"x",""))/Assumptions!$C$17)) -> 2.4327521 | C14: =(('Income Stmt'!$G$12*VALUE(SUBSTITUTE(C$11,"x",""))-'Debt Schedule'!$G$21*(VALUE(SUBSTITUTE($A14,"x",""))/Assumptions!$C$17))*Returns!$B$9)/(Returns!$B$13*(VALUE(SUBSTITUTE($A14,"x",""))/Assumptions!$C$17)) -> 2.6807571 | D14: =(('Income Stmt'!$G$12*VALUE(SUBSTITUTE(D$11,"x",""))-'Debt Schedule'!$G$21*(VALUE(SUBSTITUTE($A14,"x",""))/Assumptions!$C$17))*Returns!$B$9)/(Returns!$B$13*(VALUE(SUBSTITUTE($A14,"x",""))/Assumptions!$C$17)) -> 2.9287622 | E14: =(('Income Stmt'!$G$12*VALUE(SUBSTITUTE(E$11,"x",""))-'Debt Schedule'!$G$21*(VALUE(SUBSTITUTE($A14,"x",""))/Assumptions!$C$17))*Returns!$B$9)/(Returns!$B$13*(VALUE(SUBSTITUTE($A14,"x",""))/Assumptions!$C$17)) -> 3.1767672 | F14: =(('Income Stmt'!$G$12*VALUE(SUBSTITUTE(F$11,"x",""))-'Debt Schedule'!$G$21*(VALUE(SUBSTITUTE($A14,"x",""))/Assumptions!$C$17))*Returns!$B$9)/(Returns!$B$13*(VALUE(SUBSTITUTE($A14,"x",""))/Assumptions!$C$17)) -> 3.4247723
A15: 19.5x | B15: =(('Income Stmt'!$G$12*VALUE(SUBSTITUTE(B$11,"x",""))-'Debt Schedule'!$G$21*(VALUE(SUBSTITUTE($A15,"x",""))/Assumptions!$C$17))*Returns!$B$9)/(Returns!$B$13*(VALUE(SUBSTITUTE($A15,"x",""))/Assumptions!$C$17)) -> 2.2674154 | C15: =(('Income Stmt'!$G$12*VALUE(SUBSTITUTE(C$11,"x",""))-'Debt Schedule'!$G$21*(VALUE(SUBSTITUTE($A15,"x",""))/Assumptions!$C$17))*Returns!$B$9)/(Returns!$B$13*(VALUE(SUBSTITUTE($A15,"x",""))/Assumptions!$C$17)) -> 2.5027022 | D15: =(('Income Stmt'!$G$12*VALUE(SUBSTITUTE(D$11,"x",""))-'Debt Schedule'!$G$21*(VALUE(SUBSTITUTE($A15,"x",""))/Assumptions!$C$17))*Returns!$B$9)/(Returns!$B$13*(VALUE(SUBSTITUTE($A15,"x",""))/Assumptions!$C$17)) -> 2.7379891 | E15: =(('Income Stmt'!$G$12*VALUE(SUBSTITUTE(E$11,"x",""))-'Debt Schedule'!$G$21*(VALUE(SUBSTITUTE($A15,"x",""))/Assumptions!$C$17))*Returns!$B$9)/(Returns!$B$13*(VALUE(SUBSTITUTE($A15,"x",""))/Assumptions!$C$17)) -> 2.9732759 | F15: =(('Income Stmt'!$G$12*VALUE(SUBSTITUTE(F$11,"x",""))-'Debt Schedule'!$G$21*(VALUE(SUBSTITUTE($A15,"x",""))/Assumptions!$C$17))*Returns!$B$9)/(Returns!$B$13*(VALUE(SUBSTITUTE($A15,"x",""))/Assumptions!$C$17)) -> 3.2085628
A16: 20.5x | B16: =(('Income Stmt'!$G$12*VALUE(SUBSTITUTE(B$11,"x",""))-'Debt Schedule'!$G$21*(VALUE(SUBSTITUTE($A16,"x",""))/Assumptions!$C$17))*Returns!$B$9)/(Returns!$B$13*(VALUE(SUBSTITUTE($A16,"x",""))/Assumptions!$C$17)) -> 2.1182091 | C16: =(('Income Stmt'!$G$12*VALUE(SUBSTITUTE(C$11,"x",""))-'Debt Schedule'!$G$21*(VALUE(SUBSTITUTE($A16,"x",""))/Assumptions!$C$17))*Returns!$B$9)/(Returns!$B$13*(VALUE(SUBSTITUTE($A16,"x",""))/Assumptions!$C$17)) -> 2.3420185 | D16: =(('Income Stmt'!$G$12*VALUE(SUBSTITUTE(D$11,"x",""))-'Debt Schedule'!$G$21*(VALUE(SUBSTITUTE($A16,"x",""))/Assumptions!$C$17))*Returns!$B$9)/(Returns!$B$13*(VALUE(SUBSTITUTE($A16,"x",""))/Assumptions!$C$17)) -> 2.565828 | E16: =(('Income Stmt'!$G$12*VALUE(SUBSTITUTE(E$11,"x",""))-'Debt Schedule'!$G$21*(VALUE(SUBSTITUTE($A16,"x",""))/Assumptions!$C$17))*Returns!$B$9)/(Returns!$B$13*(VALUE(SUBSTITUTE($A16,"x",""))/Assumptions!$C$17)) -> 2.7896374 | F16: =(('Income Stmt'!$G$12*VALUE(SUBSTITUTE(F$11,"x",""))-'Debt Schedule'!$G$21*(VALUE(SUBSTITUTE($A16,"x",""))/Assumptions!$C$17))*Returns!$B$9)/(Returns!$B$13*(VALUE(SUBSTITUTE($A16,"x",""))/Assumptions!$C$17)) -> 3.0134468
A18: LEGEND (darker = higher return) · ★ = base case
A19: ≥ 30% IRR / ≥ 3.5x
A20: 24–30% / 2.9–3.5x
A21: 20–24% / 2.5–2.9x
A22: 14–20% / 1.8–2.5x
A23: < 14% / < 1.8x
A25: Note: approximation around the ACTIVE scenario. Entry-multiple axis scales invested equity
A26: and entry leverage pro-rata; operating plan held at base. Centre cell ties to the Returns tab.
